<?xml version="1.0" encoding="utf-8"?>
<!-- This URDF was automatically created by SolidWorks to URDF Exporter! Originally created by Stephen Brawner (brawner@gmail.com) 
     Commit Version: 1.6.0-4-g7f85cfe  Build Version: 1.6.7995.38578
     For more information, please see http://wiki.ros.org/sw_urdf_exporter -->
<robot
  name="urdf12">
  <link
    name="base_link">
    <inertial>
      <origin
        xyz="0.43664 -0.00014508 0.27866"
        rpy="0 0 0" />
      <mass
        value="20" />
      <inertia
        ixx="2.8213"
        ixy="-2.3059E-06"
        ixz="0.19357"
        iyy="1.7783"
        iyz="7.5845E-06"
        izz="2.242" />
    </inertial>
    <visual>
      <origin
        xyz="0 0 0"
        rpy="0 0 0" />
      <geometry>
        <mesh
          filename="package://urdf12/meshes/base_link.STL" />
      </geometry>
      <material
        name="">
        <color
          rgba="1 1 0 1" />
      </material>
    </visual>
    <collision>
      <origin
        xyz="0 0 0"
        rpy="0 0 0" />
      <geometry>
        <mesh
          filename="package://urdf12/meshes/base_link.STL" />
      </geometry>
    </collision>
  </link>
  <link
    name="wheel_l">
    <inertial>
      <origin
        xyz="-2.5707E-17 -5.5511E-17 5.5511E-17"
        rpy="0 0 0" />
      <mass
        value="4.3026" />
      <inertia
        ixx="0.02666"
        ixy="2.7995E-18"
        ixz="6.3077E-18"
        iyy="0.050742"
        iyz="-9.4113E-18"
        izz="0.02666" />
    </inertial>
    <visual>
      <origin
        xyz="0 0 0"
        rpy="0 0 0" />
      <geometry>
        <mesh
          filename="package://urdf12/meshes/wheel_l.STL" />
      </geometry>
      <material
        name="">
        <color
          rgba="0.74902 0.74902 0.74902 1" />
      </material>
    </visual>
    <collision>
      <origin
        xyz="0 0 0"
        rpy="0 0 0" />
      <geometry>
        <mesh
          filename="package://urdf12/meshes/wheel_l.STL" />
      </geometry>
    </collision>
  </link>
  <joint
    name="wheel_l_joint"
    type="continuous">
    <origin
      xyz="0 0.410288 0.1524"
      rpy="0 0 0" />
    <parent
      link="base_link" />
    <child
      link="wheel_l" />
    <axis
      xyz="0 1 0" />
    <limit effort="100" velocity="100"/>
    
  </joint>
  <link
    name="wheel_r">
    <inertial>
      <origin
        xyz="-2.8334E-17 -5.5511E-17 2.7756E-17"
        rpy="0 0 0" />
      <mass
        value="4.3026" />
      <inertia
        ixx="0.02666"
        ixy="-1.9771E-17"
        ixz="5.6705E-18"
        iyy="0.050742"
        iyz="3.2065E-17"
        izz="0.02666" />
    </inertial>
    <visual>
      <origin
        xyz="0 0 0"
        rpy="0 0 0" />
      <geometry>
        <mesh
          filename="package://urdf12/meshes/wheel_r.STL" />
      </geometry>
      <material
        name="">
        <color
          rgba="0.74902 0.74902 0.74902 1" />
      </material>
    </visual>
    <collision>
      <origin
        xyz="0 0 0"
        rpy="0 0 0" />
      <geometry>
        <mesh
          filename="package://urdf12/meshes/wheel_r.STL" />
      </geometry>
    </collision>
  </link>
  <joint
    name="wheel_r_joint"
    type="continuous">
    <origin
      xyz="0 -0.410288 0.152400000000001"
      rpy="0 0 0" />
    <parent
      link="base_link" />
    <child
      link="wheel_r" />
    <axis
      xyz="0 1 0" />
    <limit effort="100" velocity="100"/>
   
  </joint>
  <link
    name="caster_l">
    <inertial>
      <origin
        xyz="0.0067283 -0.0021857 0.0186"
        rpy="0 0 0" />
      <mass
        value="4.3026" />
      <inertia
        ixx="0.0003702"
        ixy="3.7802E-06"
        ixz="-7.8373E-06"
        iyy="0.00064112"
        iyz="4.0024E-10"
        izz="0.00038283" />
    </inertial>
    <visual>
      <origin
        xyz="0 0 0"
        rpy="0 0 0" />
      <geometry>
        <mesh
          filename="package://urdf12/meshes/caster_l.STL" />
      </geometry>
      <material
        name="">
        <color
          rgba="1 1 0 1" />
      </material>
    </visual>
    <collision>
      <origin
        xyz="0 0 0"
        rpy="0 0 0" />
      <geometry>
        <mesh
          filename="package://urdf12/meshes/caster_l.STL" />
      </geometry>
    </collision>
  </link>
  <joint
    name="caster_l_joint"
    type="fixed">
    <origin
      xyz="0.531650359845262 0.211308482486839 0.0641182418155545"
      rpy="0 0 0" />
    <parent
      link="base_link" />
    <child
      link="caster_l" />
    <axis
      xyz="0 0 0" />
  </joint>
  <link
    name="caster_r">
    <inertial>
      <origin
        xyz="0.0067283 -0.0021857 0.0186"
        rpy="0 0 0" />
      <mass
        value="4.3026" />
      <inertia
        ixx="0.0003702"
        ixy="3.7802E-06"
        ixz="-7.8373E-06"
        iyy="0.00064112"
        iyz="4.0024E-10"
        izz="0.00038283" />
    </inertial>
    <visual>
      <origin
        xyz="0 0 0"
        rpy="0 0 0" />
      <geometry>
        <mesh
          filename="package://urdf12/meshes/caster_r.STL" />
      </geometry>
      <material
        name="">
        <color
          rgba="1 1 0 1" />
      </material>
    </visual>
    <collision>
      <origin
        xyz="0 0 0"
        rpy="0 0 0" />
      <geometry>
        <mesh
          filename="package://urdf12/meshes/caster_r.STL" />
      </geometry>
    </collision>
  </link>
  <joint
    name="caster_r_joint"
    type="fixed">
    <origin
      xyz="0.531650359845262 -0.206968342140862 0.0641182418155533"
      rpy="0 0 0" />
    <parent
      link="base_link" />
    <child
      link="caster_r" />
    <axis
      xyz="0 0 0" />
  </joint>
  <link
    name="lidar">
    <inertial>
      <origin
        xyz="-0.006576 0.00028229 0.00095366"
        rpy="0 0 0" />
      <mass
        value="0.075506" />
      <inertia
        ixx="1.604E-05"
        ixy="-1.6429E-07"
        ixz="-2.907E-08"
        iyy="2.2741E-05"
        iyz="5.8948E-09"
        izz="3.5689E-05" />
    </inertial>
    <visual>
      <origin
        xyz="0 0 0"
        rpy="0 0 0" />
      <geometry>
        <mesh
          filename="package://urdf12/meshes/lidar.STL" />
      </geometry>
      <material
        name="">
        <color
          rgba="0.027451 0 0.81176 1" />
      </material>
    </visual>
    <collision>
      <origin
        xyz="0 0 0"
        rpy="0 0 0" />
      <geometry>
        <mesh
          filename="package://urdf12/meshes/lidar.STL" />
      </geometry>
    </collision>
  </link>
  <joint
    name="lidar_joint"
    type="fixed">
    <origin
      xyz="0.490449999999999 0.00401119967305881 0.409350000000001"
      rpy="0 0 0" />
    <parent
      link="base_link" />
    <child
      link="lidar" />
    <axis
      xyz="0 0 0" />
  </joint>
  <link
    name="IMU_link">
    <inertial>
      <origin
        xyz="0 -2.0577E-18 -0.004"
        rpy="0 0 0" />
      <mass
        value="0.0384" />
      <inertia
        ixx="1.1725E-05"
        ixy="1.1294E-21"
        ixz="-4.9677E-21"
        iyy="2.0685E-05"
        iyz="2.7671E-37"
        izz="3.2E-05" />
    </inertial>
    <visual>
      <origin
        xyz="0 0 0"
        rpy="0 0 0" />
      <geometry>
        <mesh
          filename="package://urdf12/meshes/IMU_link.STL" />
      </geometry>
      <material
        name="">
        <color
          rgba="0.79216 0.81961 0.93333 1" />
      </material>
    </visual>
    <collision>
      <origin
        xyz="0 0 0"
        rpy="0 0 0" />
      <geometry>
        <mesh
          filename="package://urdf12/meshes/IMU_link.STL" />
      </geometry>
    </collision>
  </link>
  <joint
    name="imu_joint"
    type="fixed">
    <origin
      xyz="0.1167 0 0.2137"
      rpy="0 0 0" />
    <parent
      link="base_link" />
    <child
      link="IMU_link" />
    <axis
      xyz="0 0 0" />
  </joint>

  <transmission name="wheel1_trans">
    <type>transmission_interface/SimpleTransmission</type>
    <joint name="wheel_l_joint">
      <hardwareInterface>hardware_interface/VelocityJointInterface</hardwareInterface>
    </joint>
    <actuator name="wheel1_motor">
      <hardwareInterface>hardware_interface/VelocityJointInterface</hardwareInterface>
      <mechanicalReduction>1</mechanicalReduction>
    </actuator>
  </transmission>

  <transmission name="wheel2_trans">
    <type>transmission_interface/SimpleTransmission</type>
    <joint name="wheel_r_joint">
      <hardwareInterface>hardware_interface/VelocityJointInterface</hardwareInterface>
    </joint>
    <actuator name="wheel2_motor">
      <hardwareInterface>hardware_interface/VelocityJointInterface</hardwareInterface>
      <mechanicalReduction>1</mechanicalReduction>
    </actuator>
  </transmission>

  <gazebo reference ="base_link">
    <material>Gazebo/White</material>
  </gazebo>
  
  
  <gazebo reference="wheel_r">
    <mu1>1</mu1>
    <mu2>1</mu2>
    <kp>500000.0</kp>
    <kd>10.0</kd>
    <minDepth>0.001</minDepth>
   
    <fdir1>1 0 0</fdir1>
    <material>Gazebo/FlatBlack</material>
  </gazebo>
  
  <gazebo reference="wheel_l">
    <mu1>1.0</mu1>
    <mu2>1.0</mu2>
    <kp>500000.0</kp>
    <kd>10.0</kd>
    <minDepth>0.01</minDepth>
    
    <fdir1>1 0 0</fdir1>
    <material>Gazebo/FlatBlack</material>
  </gazebo>
  
  <gazebo reference="caster_l">
    <mu1>1</mu1>
    <mu2>1</mu2>
    <kp>500000.0</kp>
    <kd>10.0</kd>
    <minDepth>0.001</minDepth>
    
    <material>Gazebo/FlatBlack</material>
  </gazebo>
  
  <gazebo reference="caster_r">
    <mu1>1</mu1>
    <mu2>1</mu2>
    <kp>500000.0</kp>
    <kd>10.0</kd>
    <minDepth>0.01</minDepth>
    
    <material>Gazebo/FlatBlack</material>
  </gazebo>
  
  
  <gazebo>
    <plugin name="control" filename="libgazebo_ros_control.so">
      <robotNamespace>/</robotNamespace>
    </plugin>
  </gazebo>
  
</robot>
